2025-06-02 20:20:53,446 - ERROR - Exception in callback _ProactorBasePipeTransport._call_connection_lost()
handle: <Handle _ProactorBasePipeTransport._call_connection_lost()>
Traceback (most recent call last):
  File "C:\Users\doghe\AppData\Local\Programs\Python\Python313\Lib\asyncio\events.py", line 89, in _run
    self._context.run(self._callback, *self._args)
    ~~~~~~~~~~~~~~~~~^^^^^^^^^^^^^^^^^^^^^^^^^^^^^
  File "C:\Users\doghe\AppData\Local\Programs\Python\Python313\Lib\asyncio\proactor_events.py", line 165, in _call_connection_lost
    self._sock.shutdown(socket.SHUT_RDWR)
    ~~~~~~~~~~~~~~~~~~~^^^^^^^^^^^^^^^^^^
ConnectionResetError: [WinError 10054] An existing connection was forcibly closed by the remote host
2025-06-02 20:21:17,222 - ERROR - Exception in callback _ProactorBasePipeTransport._call_connection_lost()
handle: <Handle _ProactorBasePipeTransport._call_connection_lost()>
Traceback (most recent call last):
  File "C:\Users\doghe\AppData\Local\Programs\Python\Python313\Lib\asyncio\events.py", line 89, in _run
    self._context.run(self._callback, *self._args)
    ~~~~~~~~~~~~~~~~~^^^^^^^^^^^^^^^^^^^^^^^^^^^^^
  File "C:\Users\doghe\AppData\Local\Programs\Python\Python313\Lib\asyncio\proactor_events.py", line 165, in _call_connection_lost
    self._sock.shutdown(socket.SHUT_RDWR)
    ~~~~~~~~~~~~~~~~~~~^^^^^^^^^^^^^^^^^^
ConnectionResetError: [WinError 10054] An existing connection was forcibly closed by the remote host
2025-06-02 20:21:29,604 - ERROR - Exception in callback _ProactorBasePipeTransport._call_connection_lost()
handle: <Handle _ProactorBasePipeTransport._call_connection_lost()>
Traceback (most recent call last):
  File "C:\Users\doghe\AppData\Local\Programs\Python\Python313\Lib\asyncio\events.py", line 89, in _run
    self._context.run(self._callback, *self._args)
    ~~~~~~~~~~~~~~~~~^^^^^^^^^^^^^^^^^^^^^^^^^^^^^
  File "C:\Users\doghe\AppData\Local\Programs\Python\Python313\Lib\asyncio\proactor_events.py", line 165, in _call_connection_lost
    self._sock.shutdown(socket.SHUT_RDWR)
    ~~~~~~~~~~~~~~~~~~~^^^^^^^^^^^^^^^^^^
ConnectionResetError: [WinError 10054] An existing connection was forcibly closed by the remote host
2025-06-02 20:27:29,887 - ERROR - Timeout downloading Burnout (USA).zip
2025-06-02 20:31:23,430 - ERROR - Exception in callback _ProactorBasePipeTransport._call_connection_lost()
handle: <Handle _ProactorBasePipeTransport._call_connection_lost()>
Traceback (most recent call last):
  File "C:\Users\doghe\AppData\Local\Programs\Python\Python313\Lib\asyncio\events.py", line 89, in _run
    self._context.run(self._callback, *self._args)
    ~~~~~~~~~~~~~~~~~^^^^^^^^^^^^^^^^^^^^^^^^^^^^^
  File "C:\Users\doghe\AppData\Local\Programs\Python\Python313\Lib\asyncio\proactor_events.py", line 165, in _call_connection_lost
    self._sock.shutdown(socket.SHUT_RDWR)
    ~~~~~~~~~~~~~~~~~~~^^^^^^^^^^^^^^^^^^
ConnectionResetError: [WinError 10054] An existing connection was forcibly closed by the remote host
2025-06-02 20:39:28,894 - ERROR - Timeout downloading Crash Tag Team Racing (USA).zip
