2025-06-02 18:38:05,329 - ERROR - Exception in callback _ProactorBasePipeTransport._call_connection_lost()
handle: <Handle _ProactorBasePipeTransport._call_connection_lost()>
Traceback (most recent call last):
  File "C:\Users\doghe\AppData\Local\Programs\Python\Python313\Lib\asyncio\events.py", line 89, in _run
    self._context.run(self._callback, *self._args)
    ~~~~~~~~~~~~~~~~~^^^^^^^^^^^^^^^^^^^^^^^^^^^^^
  File "C:\Users\doghe\AppData\Local\Programs\Python\Python313\Lib\asyncio\proactor_events.py", line 165, in _call_connection_lost
    self._sock.shutdown(socket.SHUT_RDWR)
    ~~~~~~~~~~~~~~~~~~~^^^^^^^^^^^^^^^^^^
ConnectionResetError: [WinError 10054] An existing connection was forcibly closed by the remote host
